[2025-08-07 16:55:06] ERROR [app:154] Error: 'DummyConnection' object has no attribute 'rollback' | Context: {'route': '/select-type'}
Traceback: Traceback (most recent call last):
  File "C:\workspace\project_lec\ai-skill-tutor\backend\app\routes\diagnosis\submit.py", line 126, in select_user_type
    update_user_type_in_db(current_user['user_id'], selected_type, connection)
    ~~~~~~~~~~~~~~~~~~~~~~^^^^^^^^^^^^^^^^^^^^^^^^^^^^^^^^^^^^^^^^^^^^^^^^^^^^
  File "C:\workspace\project_lec\ai-skill-tutor\backend\app\services\diagnosis_service.py", line 33, in update_user_type_in_db
    with connection.cursor() as cursor:
         ~~~~~~~~~~~~~~~~~^^
TypeError: 'DummyCursor' object does not support the context manager protocol

During handling of the above exception, another exception occurred:

Traceback (most recent call last):
  File "C:\workspace\project_lec\ai-skill-tutor\backend\app\routes\diagnosis\submit.py", line 128, in select_user_type
    connection.rollback()
    ^^^^^^^^^^^^^^^^^^^
AttributeError: 'DummyConnection' object has no attribute 'rollback'

[2025-08-07 16:57:04] ERROR [app:154] Error: 'DummyConnection' object has no attribute 'rollback' | Context: {'route': '/select-type'}
Traceback: Traceback (most recent call last):
  File "C:\workspace\project_lec\ai-skill-tutor\backend\app\routes\diagnosis\submit.py", line 126, in select_user_type
    update_user_type_in_db(current_user['user_id'], selected_type, connection)
    ~~~~~~~~~~~~~~~~~~~~~~^^^^^^^^^^^^^^^^^^^^^^^^^^^^^^^^^^^^^^^^^^^^^^^^^^^^
  File "C:\workspace\project_lec\ai-skill-tutor\backend\app\services\diagnosis_service.py", line 33, in update_user_type_in_db
    with connection.cursor() as cursor:
         ~~~~~~~~~~~~~~~~~^^
TypeError: 'DummyCursor' object does not support the context manager protocol

During handling of the above exception, another exception occurred:

Traceback (most recent call last):
  File "C:\workspace\project_lec\ai-skill-tutor\backend\app\routes\diagnosis\submit.py", line 128, in select_user_type
    connection.rollback()
    ^^^^^^^^^^^^^^^^^^^
AttributeError: 'DummyConnection' object has no attribute 'rollback'

[2025-08-07 16:58:26] ERROR [app:154] Error: 'DummyConnection' object has no attribute 'rollback' | Context: {'route': '/select-type'}
Traceback: Traceback (most recent call last):
  File "C:\workspace\project_lec\ai-skill-tutor\backend\app\routes\diagnosis\submit.py", line 126, in select_user_type
    update_user_type_in_db(current_user['user_id'], selected_type, connection)
    ~~~~~~~~~~~~~~~~~~~~~~^^^^^^^^^^^^^^^^^^^^^^^^^^^^^^^^^^^^^^^^^^^^^^^^^^^^
  File "C:\workspace\project_lec\ai-skill-tutor\backend\app\services\diagnosis_service.py", line 33, in update_user_type_in_db
    with connection.cursor() as cursor:
         ~~~~~~~~~~~~~~~~~^^
TypeError: 'DummyCursor' object does not support the context manager protocol

During handling of the above exception, another exception occurred:

Traceback (most recent call last):
  File "C:\workspace\project_lec\ai-skill-tutor\backend\app\routes\diagnosis\submit.py", line 128, in select_user_type
    connection.rollback()
    ^^^^^^^^^^^^^^^^^^^
AttributeError: 'DummyConnection' object has no attribute 'rollback'

[2025-08-07 16:59:13] ERROR [app:154] Error: 'DummyConnection' object has no attribute 'rollback' | Context: {'route': '/select-type'}
Traceback: Traceback (most recent call last):
  File "C:\workspace\project_lec\ai-skill-tutor\backend\app\routes\diagnosis\submit.py", line 126, in select_user_type
    update_user_type_in_db(current_user['user_id'], selected_type, connection)
    ~~~~~~~~~~~~~~~~~~~~~~^^^^^^^^^^^^^^^^^^^^^^^^^^^^^^^^^^^^^^^^^^^^^^^^^^^^
  File "C:\workspace\project_lec\ai-skill-tutor\backend\app\services\diagnosis_service.py", line 33, in update_user_type_in_db
    with connection.cursor() as cursor:
         ~~~~~~~~~~~~~~~~~^^
TypeError: 'DummyCursor' object does not support the context manager protocol

During handling of the above exception, another exception occurred:

Traceback (most recent call last):
  File "C:\workspace\project_lec\ai-skill-tutor\backend\app\routes\diagnosis\submit.py", line 128, in select_user_type
    connection.rollback()
    ^^^^^^^^^^^^^^^^^^^
AttributeError: 'DummyConnection' object has no attribute 'rollback'

[2025-08-08 16:57:16] ERROR [app.utils.database.transaction:298] 트랜잭션 실행 오류: 'function' object is not iterable
[2025-08-08 16:57:49] ERROR [app.utils.database.transaction:298] 트랜잭션 실행 오류: 'function' object is not iterable
[2025-08-08 16:59:14] ERROR [app.utils.database.transaction:298] 트랜잭션 실행 오류: 'function' object is not iterable
[2025-08-11 16:16:48] ERROR [app:143] Error: '_GeneratorContextManager' object has no attribute 'close' | Context: {'route': '/select-type'}
Traceback: Traceback (most recent call last):
  File "C:\workspace\project_lec\ai-skill-tutor\backend\app\routes\diagnosis\submit.py", line 126, in select_user_type
    update_user_type_in_db(current_user['user_id'], selected_type, connection)
    ~~~~~~~~~~~~~~~~~~~~~~^^^^^^^^^^^^^^^^^^^^^^^^^^^^^^^^^^^^^^^^^^^^^^^^^^^^
  File "C:\workspace\project_lec\ai-skill-tutor\backend\app\services\diagnosis_service.py", line 33, in update_user_type_in_db
    with connection.cursor() as cursor:
         ^^^^^^^^^^^^^^^^^
AttributeError: '_GeneratorContextManager' object has no attribute 'cursor'

During handling of the above exception, another exception occurred:

Traceback (most recent call last):
  File "C:\workspace\project_lec\ai-skill-tutor\backend\app\routes\diagnosis\submit.py", line 128, in select_user_type
    connection.rollback()
    ^^^^^^^^^^^^^^^^^^^
AttributeError: '_GeneratorContextManager' object has no attribute 'rollback'

During handling of the above exception, another exception occurred:

Traceback (most recent call last):
  File "C:\workspace\project_lec\ai-skill-tutor\backend\app\routes\diagnosis\submit.py", line 138, in select_user_type
    connection.close()
    ^^^^^^^^^^^^^^^^
AttributeError: '_GeneratorContextManager' object has no attribute 'close'

[2025-08-11 16:32:39] ERROR [app:143] Error: '_GeneratorContextManager' object has no attribute 'close' | Context: {'route': '/select-type'}
Traceback: Traceback (most recent call last):
  File "C:\workspace\project_lec\ai-skill-tutor\backend\app\routes\diagnosis\submit.py", line 126, in select_user_type
    update_user_type_in_db(current_user['user_id'], selected_type, connection)
    ~~~~~~~~~~~~~~~~~~~~~~^^^^^^^^^^^^^^^^^^^^^^^^^^^^^^^^^^^^^^^^^^^^^^^^^^^^
  File "C:\workspace\project_lec\ai-skill-tutor\backend\app\services\diagnosis_service.py", line 33, in update_user_type_in_db
    with connection.cursor() as cursor:
         ^^^^^^^^^^^^^^^^^
AttributeError: '_GeneratorContextManager' object has no attribute 'cursor'

During handling of the above exception, another exception occurred:

Traceback (most recent call last):
  File "C:\workspace\project_lec\ai-skill-tutor\backend\app\routes\diagnosis\submit.py", line 128, in select_user_type
    connection.rollback()
    ^^^^^^^^^^^^^^^^^^^
AttributeError: '_GeneratorContextManager' object has no attribute 'rollback'

During handling of the above exception, another exception occurred:

Traceback (most recent call last):
  File "C:\workspace\project_lec\ai-skill-tutor\backend\app\routes\diagnosis\submit.py", line 138, in select_user_type
    connection.close()
    ^^^^^^^^^^^^^^^^
AttributeError: '_GeneratorContextManager' object has no attribute 'close'

[2025-08-20 13:02:30] ERROR [app.agents.evaluation_feedback.evaluation_feedback_agent:107] 퀴즈 내용이 비어있습니다.
[2025-08-20 13:02:30] ERROR [app.agents.evaluation_feedback.evaluation_feedback_agent:266] 오류 상태 생성: State 검증 실패
[2025-08-20 13:04:38] ERROR [app.agents.evaluation_feedback.evaluation_feedback_agent:107] 퀴즈 내용이 비어있습니다.
[2025-08-20 13:04:38] ERROR [app.agents.evaluation_feedback.evaluation_feedback_agent:266] 오류 상태 생성: State 검증 실패
[2025-08-20 13:06:50] ERROR [app.agents.evaluation_feedback.evaluation_feedback_agent:107] 퀴즈 내용이 비어있습니다.
[2025-08-20 13:06:50] ERROR [app.agents.evaluation_feedback.evaluation_feedback_agent:266] 오류 상태 생성: State 검증 실패
[2025-08-20 13:15:44] ERROR [app.core.langraph.workflow:91] [exec_1755663344] 워크플로우 실행 실패: Invalid TutorState provided
[2025-08-20 13:21:08] ERROR [app.core.langraph.workflow:91] [exec_1755663668] 워크플로우 실행 실패: Invalid TutorState provided
[2025-08-20 13:22:53] ERROR [app.core.langraph.workflow:91] [exec_1755663773] 워크플로우 실행 실패: Invalid TutorState provided
[2025-08-20 13:24:37] ERROR [app.core.langraph.workflow:91] [exec_1755663877] 워크플로우 실행 실패: Invalid TutorState provided
[2025-08-20 13:36:32] ERROR [app.core.langraph.workflow:91] [exec_1755664592] 워크플로우 실행 실패: Invalid TutorState provided
[2025-08-20 13:44:57] ERROR [app.core.langraph.workflow:91] [exec_1755665097] 워크플로우 실행 실패: Invalid TutorState provided
[2025-08-20 13:59:25] ERROR [app.core.langraph.workflow:91] [exec_1755665965] 워크플로우 실행 실패: Invalid TutorState provided
[2025-08-20 14:04:31] ERROR [app.core.langraph.workflow:91] [exec_1755666271] 워크플로우 실행 실패: Invalid TutorState provided
[2025-08-20 14:10:26] ERROR [app.core.langraph.workflow:157] 표준 실행 중 오류: Event loop is closed
[2025-08-20 14:10:26] ERROR [app.core.langraph.workflow:91] [exec_1755666616] 워크플로우 실행 실패: Event loop is closed
[2025-08-20 14:20:27] ERROR [app.core.langraph.workflow:157] 표준 실행 중 오류: Event loop is closed
[2025-08-20 14:20:27] ERROR [app.core.langraph.workflow:91] [exec_1755667224] 워크플로우 실행 실패: Event loop is closed
[2025-08-20 14:40:10] ERROR [app.services.dashboard.dashboard_service:91] 대시보드 조회 데이터베이스 오류: DB 연결 실패
[2025-08-20 14:40:10] ERROR [app.services.dashboard.dashboard_service:94] 대시보드 조회 예상치 못한 오류: 예상치 못한 오류
[2025-08-20 14:40:10] ERROR [app.services.dashboard.dashboard_service:269] 챕터 메타데이터 파일을 찾을 수 없습니다: C:\workspace\project_lec\ai-skill-tutor\backend\app\data\chapters\chapters_metadata.json
[2025-08-20 14:40:10] ERROR [app.services.dashboard.dashboard_service:272] 챕터 메타데이터 JSON 파싱 오류: JSON 파싱 오류: line 1 column 1 (char 0)
[2025-08-20 14:40:10] ERROR [app.services.dashboard.dashboard_service:275] 챕터 메타데이터 로드 오류: 예상치 못한 오류
[2025-08-20 14:40:10] ERROR [app.services.dashboard.dashboard_service:414] 진행률 계산 오류: 메타데이터 로드 오류
[2025-08-20 14:40:10] ERROR [app.services.dashboard.dashboard_service:245] 챕터 상태 조회 오류: 메타데이터 로드 오류
[2025-08-20 14:42:42] ERROR [app.services.dashboard.dashboard_service:91] 대시보드 조회 데이터베이스 오류: DB 연결 실패
[2025-08-20 14:42:42] ERROR [app.services.dashboard.dashboard_service:94] 대시보드 조회 예상치 못한 오류: 예상치 못한 오류
[2025-08-20 14:42:42] ERROR [app.services.dashboard.dashboard_service:269] 챕터 메타데이터 파일을 찾을 수 없습니다: C:\workspace\project_lec\ai-skill-tutor\backend\app\data\chapters\chapters_metadata.json
[2025-08-20 14:42:42] ERROR [app.services.dashboard.dashboard_service:272] 챕터 메타데이터 JSON 파싱 오류: JSON 파싱 오류: line 1 column 1 (char 0)
[2025-08-20 14:42:42] ERROR [app.services.dashboard.dashboard_service:275] 챕터 메타데이터 로드 오류: 예상치 못한 오류
[2025-08-20 14:42:42] ERROR [app.services.dashboard.dashboard_service:414] 진행률 계산 오류: 메타데이터 로드 오류
[2025-08-20 14:42:42] ERROR [app.services.dashboard.dashboard_service:245] 챕터 상태 조회 오류: 메타데이터 로드 오류
[2025-08-20 14:51:51] ERROR [app.services.dashboard.dashboard_service:269] 챕터 메타데이터 파일을 찾을 수 없습니다: C:\workspace\project_lec\ai-skill-tutor\backend\app\data\chapters\chapters_metadata.json
[2025-08-20 14:51:51] ERROR [app.services.dashboard.dashboard_service:269] 챕터 메타데이터 파일을 찾을 수 없습니다: C:\workspace\project_lec\ai-skill-tutor\backend\app\data\chapters\chapters_metadata.json
[2025-08-20 14:51:51] ERROR [app.services.dashboard.dashboard_service:414] 진행률 계산 오류: 'total_sections'
[2025-08-20 14:59:44] ERROR [app.utils.database.connection:375] 예상치 못한 단일 레코드 조회 오류: 'NoneType' object has no attribute 'get_connection'
[2025-08-20 15:12:08] ERROR [app.services.dashboard.dashboard_service:91] 대시보드 조회 데이터베이스 오류: DB 연결 실패
[2025-08-20 15:12:08] ERROR [app.services.dashboard.dashboard_service:94] 대시보드 조회 예상치 못한 오류: 예상치 못한 오류
[2025-08-20 15:12:08] ERROR [app.services.dashboard.dashboard_service:269] 챕터 메타데이터 파일을 찾을 수 없습니다: C:\workspace\project_lec\ai-skill-tutor\backend\data\chapters\chapters_metadata.json
[2025-08-20 15:12:08] ERROR [app.services.dashboard.dashboard_service:272] 챕터 메타데이터 JSON 파싱 오류: JSON 파싱 오류: line 1 column 1 (char 0)
[2025-08-20 15:12:08] ERROR [app.services.dashboard.dashboard_service:275] 챕터 메타데이터 로드 오류: 예상치 못한 오류
[2025-08-20 15:12:08] ERROR [app.services.dashboard.dashboard_service:414] 진행률 계산 오류: 메타데이터 로드 오류
[2025-08-20 15:12:08] ERROR [app.services.dashboard.dashboard_service:245] 챕터 상태 조회 오류: 메타데이터 로드 오류
[2025-08-20 15:15:57] ERROR [app.utils.database.connection:375] 예상치 못한 단일 레코드 조회 오류: 'NoneType' object has no attribute 'get_connection'
[2025-08-20 15:38:08] ERROR [app.utils.database.connection:375] 예상치 못한 단일 레코드 조회 오류: 'NoneType' object has no attribute 'get_connection'
[2025-08-20 15:49:48] ERROR [app.tools.content.theory_tools_chatgpt:53] ChatGPT 이론 설명 생성 실패: Error code: 500
[2025-08-20 15:50:23] ERROR [app.tools.content.quiz_tools_chatgpt:63] ChatGPT 퀴즈 생성 실패: Error code: 500
[2025-08-20 15:50:40] ERROR [app.tools.content.feedback_tools_chatgpt:109] ChatGPT 객관식 피드백 생성 실패: Error code: 500
[2025-08-20 15:51:13] ERROR [app.tools.content.quiz_tools_chatgpt:63] ChatGPT 퀴즈 생성 실패: Error code: 500
[2025-08-20 15:51:15] ERROR [app.tools.content.theory_tools_chatgpt:53] ChatGPT 이론 설명 생성 실패: Error code: 500
[2025-08-20 16:08:40] ERROR [app.utils.database.connection:375] 예상치 못한 단일 레코드 조회 오류: 'NoneType' object has no attribute 'get_connection'
[2025-08-20 16:41:34] ERROR [app.utils.database.connection:274] 데이터베이스 무결성 오류: (1452, 'Cannot add or update a child row: a foreign key constraint fails (`mas_ai_tutor`.`user_auth_tokens`, CONSTRAINT `user_auth_tokens_ibfk_1` FOREIGN KEY (`user_id`) REFERENCES `users` (`user_id`) ON DELETE CASCADE)')
[2025-08-20 16:59:37] ERROR [app.utils.database.connection:375] 예상치 못한 단일 레코드 조회 오류: 'NoneType' object has no attribute 'get_connection'
[2025-08-20 17:01:53] ERROR [app.utils.database.query_builder:300] 레코드 삽입 오류 (session_quizzes): (1241, 'Operand should contain 1 column(s)')
[2025-08-20 17:01:53] ERROR [app.agents.session_manager.session_handlers:159] 퀴즈 정보 저장 쿼리 오류: 레코드 삽입 오류 (session_quizzes): (1241, 'Operand should contain 1 column(s)')
[2025-08-20 17:05:57] ERROR [app.utils.database.query_builder:300] 레코드 삽입 오류 (session_quizzes): (1241, 'Operand should contain 1 column(s)')
[2025-08-20 17:05:57] ERROR [app.agents.session_manager.session_handlers:159] 퀴즈 정보 저장 쿼리 오류: 레코드 삽입 오류 (session_quizzes): (1241, 'Operand should contain 1 column(s)')
[2025-08-20 17:07:25] ERROR [app.utils.database.query_builder:300] 레코드 삽입 오류 (session_quizzes): (1241, 'Operand should contain 1 column(s)')
[2025-08-20 17:07:25] ERROR [app.agents.session_manager.session_handlers:159] 퀴즈 정보 저장 쿼리 오류: 레코드 삽입 오류 (session_quizzes): (1241, 'Operand should contain 1 column(s)')
[2025-08-20 17:22:50] ERROR [app.utils.database.connection:375] 예상치 못한 단일 레코드 조회 오류: 'NoneType' object has no attribute 'get_connection'
[2025-08-20 17:25:57] ERROR [app.utils.database.connection:375] 예상치 못한 단일 레코드 조회 오류: 'NoneType' object has no attribute 'get_connection'
[2025-08-20 17:33:55] ERROR [app.utils.database.connection:375] 예상치 못한 단일 레코드 조회 오류: 'NoneType' object has no attribute 'get_connection'
[2025-08-20 17:36:35] ERROR [app.utils.database.query_builder:300] 레코드 삽입 오류 (session_quizzes): (1241, 'Operand should contain 1 column(s)')
[2025-08-20 17:36:35] ERROR [app.agents.session_manager.session_handlers:159] 퀴즈 정보 저장 쿼리 오류: 레코드 삽입 오류 (session_quizzes): (1241, 'Operand should contain 1 column(s)')
[2025-08-20 17:55:59] ERROR [app.utils.database.query_builder:300] 레코드 삽입 오류 (session_quizzes): (1241, 'Operand should contain 1 column(s)')
[2025-08-20 17:55:59] ERROR [app.agents.session_manager.session_handlers:159] 퀴즈 정보 저장 쿼리 오류: 레코드 삽입 오류 (session_quizzes): (1241, 'Operand should contain 1 column(s)')
[2025-08-22 15:54:27] ERROR [app.agents.session_manager.session_manager_agent:77] [session_manager] 세션 처리 중 오류: cannot access local variable 'updated_state' where it is not associated with a value
[2025-08-22 15:54:27] ERROR [app.agents.session_manager.session_manager_agent:412] 오류 처리 및 정리: cannot access local variable 'updated_state' where it is not associated with a value
[2025-08-23 13:28:55] ERROR [app.utils.database.connection:380] 단일 레코드 조회 실패 (최대 재시도 횟수 초과): (1054, "Unknown column 'total_study_time_minutes' in 'field list'")
[2025-08-23 13:28:55] ERROR [app.services.dashboard.dashboard_service:91] 대시보드 조회 데이터베이스 오류: 단일 레코드 조회 실패 (최대 재시도 횟수 초과): (1054, "Unknown column 'total_study_time_minutes' in 'field list'")
[2025-08-23 13:30:49] ERROR [app.utils.database.connection:380] 단일 레코드 조회 실패 (최대 재시도 횟수 초과): (1054, "Unknown column 'total_study_time_minutes' in 'field list'")
[2025-08-23 13:30:49] ERROR [app.services.dashboard.dashboard_service:91] 대시보드 조회 데이터베이스 오류: 단일 레코드 조회 실패 (최대 재시도 횟수 초과): (1054, "Unknown column 'total_study_time_minutes' in 'field list'")
[2025-08-23 13:31:58] ERROR [app.utils.database.connection:380] 단일 레코드 조회 실패 (최대 재시도 횟수 초과): (1054, "Unknown column 'total_study_time_minutes' in 'field list'")
[2025-08-23 13:31:58] ERROR [app.services.dashboard.dashboard_service:91] 대시보드 조회 데이터베이스 오류: 단일 레코드 조회 실패 (최대 재시도 횟수 초과): (1054, "Unknown column 'total_study_time_minutes' in 'field list'")
[2025-08-23 13:32:02] ERROR [app.utils.database.connection:380] 단일 레코드 조회 실패 (최대 재시도 횟수 초과): (1054, "Unknown column 'total_study_time_minutes' in 'field list'")
[2025-08-23 13:32:02] ERROR [app.services.dashboard.dashboard_service:91] 대시보드 조회 데이터베이스 오류: 단일 레코드 조회 실패 (최대 재시도 횟수 초과): (1054, "Unknown column 'total_study_time_minutes' in 'field list'")
[2025-08-23 13:32:11] ERROR [app.utils.database.connection:380] 단일 레코드 조회 실패 (최대 재시도 횟수 초과): (1054, "Unknown column 'total_study_time_minutes' in 'field list'")
[2025-08-23 13:32:11] ERROR [app.services.dashboard.dashboard_service:91] 대시보드 조회 데이터베이스 오류: 단일 레코드 조회 실패 (최대 재시도 횟수 초과): (1054, "Unknown column 'total_study_time_minutes' in 'field list'")
[2025-08-23 13:32:17] ERROR [app.utils.database.connection:380] 단일 레코드 조회 실패 (최대 재시도 횟수 초과): (1054, "Unknown column 'total_study_time_minutes' in 'field list'")
[2025-08-23 13:32:17] ERROR [app.services.dashboard.dashboard_service:91] 대시보드 조회 데이터베이스 오류: 단일 레코드 조회 실패 (최대 재시도 횟수 초과): (1054, "Unknown column 'total_study_time_minutes' in 'field list'")
[2025-08-23 13:33:18] ERROR [app.utils.database.connection:380] 단일 레코드 조회 실패 (최대 재시도 횟수 초과): (1054, "Unknown column 'total_study_time_minutes' in 'field list'")
[2025-08-23 13:33:18] ERROR [app.services.dashboard.dashboard_service:91] 대시보드 조회 데이터베이스 오류: 단일 레코드 조회 실패 (최대 재시도 횟수 초과): (1054, "Unknown column 'total_study_time_minutes' in 'field list'")
[2025-08-23 14:15:41] ERROR [app.utils.database.query_builder:304] 예상치 못한 레코드 삽입 오류 (learning_sessions): dict can not be used as parameter
[2025-08-23 14:15:41] ERROR [app.agents.session_manager.session_handlers:68] 세션 정보 저장 쿼리 오류: 예상치 못한 레코드 삽입 오류 (learning_sessions): dict can not be used as parameter
[2025-08-23 14:15:41] ERROR [app.agents.session_manager.session_manager_agent:271] DB 저장 중 오류: 세션 ID 생성 실패
[2025-08-23 14:20:29] ERROR [app.utils.database.query_builder:300] 레코드 삽입 오류 (learning_sessions): (1054, "Unknown column 'next_chapter' in 'field list'")
[2025-08-23 14:20:29] ERROR [app.agents.session_manager.session_handlers:68] 세션 정보 저장 쿼리 오류: 레코드 삽입 오류 (learning_sessions): (1054, "Unknown column 'next_chapter' in 'field list'")
[2025-08-23 14:20:29] ERROR [app.agents.session_manager.session_manager_agent:271] DB 저장 중 오류: 세션 ID 생성 실패
[2025-08-24 13:46:44] ERROR [app.utils.database.connection:375] 예상치 못한 단일 레코드 조회 오류: 'NoneType' object has no attribute 'get_connection'
[2025-08-24 16:32:49] ERROR [app.tools.content.qna_tools_chatgpt:76] QnA Agent 답변 생성 실패: 'Input to ChatPromptTemplate is missing variables {\'\\n  "learning_context"\'}.  Expected: [\'\\n  "learning_context"\', \'input\'] Received: [\'input\', \'intermediate_steps\', \'agent_scratchpad\']\nNote: if you intended {\n  "learning_context"} to be part of the string and not a variable, please escape it with double curly braces like: \'{{\n  "learning_context"}}\'.\nFor troubleshooting, visit: https://python.langchain.com/docs/troubleshooting/errors/INVALID_PROMPT_INPUT '
[2025-08-24 16:36:40] ERROR [app.tools.content.qna_tools_chatgpt:76] QnA Agent 답변 생성 실패: 'Input to ChatPromptTemplate is missing variables {\'\\n  "learning_context"\'}.  Expected: [\'\\n  "learning_context"\', \'input\'] Received: [\'input\', \'intermediate_steps\', \'agent_scratchpad\']\nNote: if you intended {\n  "learning_context"} to be part of the string and not a variable, please escape it with double curly braces like: \'{{\n  "learning_context"}}\'.\nFor troubleshooting, visit: https://python.langchain.com/docs/troubleshooting/errors/INVALID_PROMPT_INPUT '
[2025-08-24 17:50:12] ERROR [app.tools.content.qna_tools_chatgpt:76] QnA Agent 답변 생성 실패: Got unsupported early_stopping_method `generate`
[2025-08-24 17:53:45] ERROR [app.tools.content.qna_tools_chatgpt:74] QnA Agent 답변 생성 실패: Got unsupported early_stopping_method `generate`
[2025-08-24 20:15:33] ERROR [app.tools.content.theory_tools_chatgpt:72] ChatGPT 이론 설명 생성 실패: 'Input to PromptTemplate is missing variables {\'\\n  "chapter_info"\'}.  Expected: [\'\\n  "chapter_info"\', \'chapter_title\', \'section_title\', \'vector_content\'] Received: [\'chapter_title\', \'section_title\', \'vector_content\']\nNote: if you intended {\n  "chapter_info"} to be part of the string and not a variable, please escape it with double curly braces like: \'{{\n  "chapter_info"}}\'.\nFor troubleshooting, visit: https://python.langchain.com/docs/troubleshooting/errors/INVALID_PROMPT_INPUT '
[2025-08-24 20:15:48] ERROR [app.tools.content.theory_tools_chatgpt:72] ChatGPT 이론 설명 생성 실패: 'Input to PromptTemplate is missing variables {\'\\n  "chapter_info"\'}.  Expected: [\'\\n  "chapter_info"\', \'chapter_title\', \'section_title\', \'vector_content\'] Received: [\'chapter_title\', \'section_title\', \'vector_content\']\nNote: if you intended {\n  "chapter_info"} to be part of the string and not a variable, please escape it with double curly braces like: \'{{\n  "chapter_info"}}\'.\nFor troubleshooting, visit: https://python.langchain.com/docs/troubleshooting/errors/INVALID_PROMPT_INPUT '
[2025-08-24 20:16:33] ERROR [app.tools.content.theory_tools_chatgpt:72] ChatGPT 이론 설명 생성 실패: 'Input to PromptTemplate is missing variables {\'\\n  "chapter_info"\'}.  Expected: [\'\\n  "chapter_info"\', \'chapter_title\', \'section_title\', \'vector_content\'] Received: [\'chapter_title\', \'section_title\', \'vector_content\']\nNote: if you intended {\n  "chapter_info"} to be part of the string and not a variable, please escape it with double curly braces like: \'{{\n  "chapter_info"}}\'.\nFor troubleshooting, visit: https://python.langchain.com/docs/troubleshooting/errors/INVALID_PROMPT_INPUT '
[2025-08-24 20:16:45] ERROR [app.tools.content.theory_tools_chatgpt:72] ChatGPT 이론 설명 생성 실패: 'Input to PromptTemplate is missing variables {\'\\n  "chapter_info"\'}.  Expected: [\'\\n  "chapter_info"\', \'chapter_title\', \'section_title\', \'vector_content\'] Received: [\'chapter_title\', \'section_title\', \'vector_content\']\nNote: if you intended {\n  "chapter_info"} to be part of the string and not a variable, please escape it with double curly braces like: \'{{\n  "chapter_info"}}\'.\nFor troubleshooting, visit: https://python.langchain.com/docs/troubleshooting/errors/INVALID_PROMPT_INPUT '
[2025-08-24 21:34:53] ERROR [app.core.langraph.workflow:157] 표준 실행 중 오류: cannot schedule new futures after shutdown
[2025-08-24 21:34:53] ERROR [app.core.langraph.workflow:91] [exec_1756038886] 워크플로우 실행 실패: cannot schedule new futures after shutdown
[2025-08-24 21:46:11] ERROR [app.core.langraph.workflow:157] 표준 실행 중 오류: cannot schedule new futures after shutdown
[2025-08-24 21:46:11] ERROR [app.core.langraph.workflow:91] [exec_1756039565] 워크플로우 실행 실패: cannot schedule new futures after shutdown
[2025-08-25 00:00:44] ERROR [app.tools.content.qna_tools_chatgpt:76] QnA Agent 답변 생성 실패: The server had an error while processing your request. Sorry about that!
[2025-08-25 01:26:33] ERROR [app.tools.content.qna_tools_chatgpt:76] QnA Agent 답변 생성 실패: Got unsupported early_stopping_method `generate`
[2025-08-25 01:31:33] ERROR [app.tools.content.qna_tools_chatgpt:76] QnA Agent 답변 생성 실패: Got unsupported early_stopping_method `generate`
[2025-08-25 01:34:55] ERROR [app.tools.content.qna_tools_chatgpt:76] QnA Agent 답변 생성 실패: Got unsupported early_stopping_method `generate`
[2025-08-25 01:37:56] ERROR [app.tools.content.qna_tools_chatgpt:76] QnA Agent 답변 생성 실패: Got unsupported early_stopping_method `generate`
[2025-08-25 13:35:39] ERROR [app.core.langraph.workflow:157] 표준 실행 중 오류: cannot schedule new futures after shutdown
[2025-08-25 13:35:39] ERROR [app.core.langraph.workflow:91] [exec_1756096526] 워크플로우 실행 실패: cannot schedule new futures after shutdown
[2025-08-26 15:09:55] ERROR [app.core.langraph.workflow:157] 표준 실행 중 오류: cannot schedule new futures after shutdown
[2025-08-26 15:09:55] ERROR [app.core.langraph.workflow:91] [exec_1756188583] 워크플로우 실행 실패: cannot schedule new futures after shutdown
[2025-08-26 15:09:55] ERROR [app.core.langraph.workflow:157] 표준 실행 중 오류: cannot schedule new futures after shutdown
[2025-08-26 15:09:55] ERROR [app.core.langraph.workflow:91] [exec_1756188583] 워크플로우 실행 실패: cannot schedule new futures after shutdown
[2025-08-26 15:09:56] ERROR [app.core.langraph.workflow:157] 표준 실행 중 오류: cannot schedule new futures after shutdown
[2025-08-26 15:09:56] ERROR [app.core.langraph.workflow:91] [exec_1756188583] 워크플로우 실행 실패: cannot schedule new futures after shutdown
[2025-08-26 15:09:56] ERROR [app.core.langraph.workflow:157] 표준 실행 중 오류: cannot schedule new futures after shutdown
[2025-08-26 15:09:56] ERROR [app.core.langraph.workflow:91] [exec_1756188583] 워크플로우 실행 실패: cannot schedule new futures after shutdown
[2025-08-28 09:38:59] ERROR [app.utils.database.connection:375] 예상치 못한 단일 레코드 조회 오류: 'NoneType' object has no attribute 'get_connection'
[2025-08-28 09:39:12] ERROR [app.utils.database.connection:375] 예상치 못한 단일 레코드 조회 오류: 'NoneType' object has no attribute 'get_connection'
[2025-08-28 15:07:05] ERROR [app.utils.database.connection:375] 예상치 못한 단일 레코드 조회 오류: 'NoneType' object has no attribute 'get_connection'
[2025-08-28 16:49:49] ERROR [app.utils.database.connection:375] 예상치 못한 단일 레코드 조회 오류: 'NoneType' object has no attribute 'get_connection'
[2025-09-01 14:58:48] ERROR [app.core.langraph.workflow:91] [exec_1756706328] 워크플로우 실행 실패: Invalid TutorState provided
[2025-09-01 15:05:56] ERROR [app.utils.database.connection:375] 예상치 못한 단일 레코드 조회 오류: 'NoneType' object has no attribute 'get_connection'
[2025-09-01 15:07:59] ERROR [app.core.langraph.workflow:91] [exec_1756706879] 워크플로우 실행 실패: Invalid TutorState provided
[2025-09-03 14:47:06] ERROR [app.core.langraph.workflow:91] [exec_1756878425] 워크플로우 실행 실패: Invalid TutorState provided
[2025-09-03 14:50:47] ERROR [app.core.langraph.workflow:91] [exec_1756878647] 워크플로우 실행 실패: Invalid TutorState provided
[2025-09-03 14:50:47] ERROR [app.core.langraph.workflow:91] [exec_1756878647] 워크플로우 실행 실패: Invalid TutorState provided
